(myenv) kriminel@pop-os:~/Documents/Code/nigel$ flask run
Usage: flask run [OPTIONS]
Try 'flask run --help' for help.

Error: While importing 'wsgi', an ImportError was raised:

Traceback (most recent call last):
  File "/home/kriminel/Documents/Code/nigel/myenv/lib/python3.8/site-packages/flask/cli.py", line 219, in locate_app
    __import__(module_name)
  File "/home/kriminel/Documents/Code/nigel/wsgi.py", line 1, in <module>
    from app import app as application
  File "/home/kriminel/Documents/Code/nigel/app/__init__.py", line 2, in <module>
    from models import db
ModuleNotFoundError: No module named 'models'

(myenv) kriminel@pop-os:~/Documents/Code/nigel$ export FLASK_APP=wsgi
(myenv) kriminel@pop-os:~/Documents/Code/nigel$ flask run
Usage: flask run [OPTIONS]
Try 'flask run --help' for help.

Error: While importing 'wsgi', an ImportError was raised:

Traceback (most recent call last):
  File "/home/kriminel/Documents/Code/nigel/myenv/lib/python3.8/site-packages/flask/cli.py", line 219, in locate_app
    __import__(module_name)
  File "/home/kriminel/Documents/Code/nigel/wsgi.py", line 1, in <module>
    from app import app as application
  File "/home/kriminel/Documents/Code/nigel/app/__init__.py", line 2, in <module>
    from models import db
ModuleNotFoundError: No module named 'models'

(myenv) kriminel@pop-os:~/Documents/Code/nigel$ export FLASK_APP=app
(myenv) kriminel@pop-os:~/Documents/Code/nigel$ flask run
Usage: flask run [OPTIONS]
Try 'flask run --help' for help.

Error: While importing 'app', an ImportError was raised:

Traceback (most recent call last):
  File "/home/kriminel/Documents/Code/nigel/myenv/lib/python3.8/site-packages/flask/cli.py", line 219, in locate_app
    __import__(module_name)
  File "/home/kriminel/Documents/Code/nigel/app/__init__.py", line 2, in <module>
    from models import db
ModuleNotFoundError: No module named 'models'

(myenv) kriminel@pop-os:~/Documents/Code/nigel$ flask run
Usage: flask run [OPTIONS]
Try 'flask run --help' for help.

Error: While importing 'app', an ImportError was raised:

Traceback (most recent call last):
  File "/home/kriminel/Documents/Code/nigel/myenv/lib/python3.8/site-packages/flask/cli.py", line 219, in locate_app
    __import__(module_name)
  File "/home/kriminel/Documents/Code/nigel/app/__init__.py", line 2, in <module>
    from models import db
ModuleNotFoundError: No module named 'models'

(myenv) kriminel@pop-os:~/Documents/Code/nigel$ flask run
Usage: flask run [OPTIONS]
Try 'flask run --help' for help.

Error: While importing 'app', an ImportError was raised:

Traceback (most recent call last):
  File "/home/kriminel/Documents/Code/nigel/myenv/lib/python3.8/site-packages/flask/cli.py", line 219, in locate_app
    __import__(module_name)
  File "/home/kriminel/Documents/Code/nigel/app/__init__.py", line 3, in <module>
    from app.routes import home, post, new_post
  File "/home/kriminel/Documents/Code/nigel/app/routes.py", line 2, in <module>
    from models import db, Post
ModuleNotFoundError: No module named 'models'

(myenv) kriminel@pop-os:~/Documents/Code/nigel$ flask run
Usage: flask run [OPTIONS]
Try 'flask run --help' for help.

Error: While importing 'app', an ImportError was raised:

Traceback (most recent call last):
  File "/home/kriminel/Documents/Code/nigel/myenv/lib/python3.8/site-packages/flask/cli.py", line 219, in locate_app
    __import__(module_name)
  File "/home/kriminel/Documents/Code/nigel/app/__init__.py", line 3, in <module>
    from app.routes import home, post, new_post
  File "/home/kriminel/Documents/Code/nigel/app/routes.py", line 2, in <module>
    from models import db, Post
ModuleNotFoundError: No module named 'models'

(myenv) kriminel@pop-os:~/Documents/Code/nigel$ flask run
Usage: flask run [OPTIONS]
Try 'flask run --help' for help.

Error: While importing 'app', an ImportError was raised:

Traceback (most recent call last):
  File "/home/kriminel/Documents/Code/nigel/myenv/lib/python3.8/site-packages/flask/cli.py", line 219, in locate_app
    __import__(module_name)
  File "/home/kriminel/Documents/Code/nigel/app/__init__.py", line 3, in <module>
    from app.routes import home, post, new_post
  File "/home/kriminel/Documents/Code/nigel/app/routes.py", line 2, in <module>
    from models import db, Post
ModuleNotFoundError: No module named 'models'

(myenv) kriminel@pop-os:~/Documents/Code/nigel$ python
Python 3.8.18 (default, Oct  2 2023, 19:30:04) 
[GCC 11.4.0] on linux
Type "help", "copyright", "credits" or "license" for more information.
>>> import wsgi
Traceback (most recent call last):
  File "<stdin>", line 1, in <module>
  File "/home/kriminel/Documents/Code/nigel/wsgi.py", line 1, in <module>
    from app import app as application
  File "/home/kriminel/Documents/Code/nigel/app/__init__.py", line 3, in <module>
    from app.routes import home, post, new_post
  File "/home/kriminel/Documents/Code/nigel/app/routes.py", line 2, in <module>
    from models import db, Post
ModuleNotFoundError: No module named 'models'
>>> import app.models
Traceback (most recent call last):
  File "<stdin>", line 1, in <module>
  File "/home/kriminel/Documents/Code/nigel/app/__init__.py", line 3, in <module>
    from app.routes import home, post, new_post
  File "/home/kriminel/Documents/Code/nigel/app/routes.py", line 2, in <module>
    from models import db, Post
ModuleNotFoundError: No module named 'models'
>>> 
(myenv) kriminel@pop-os:~/Documents/Code/nigel$ python
Python 3.8.18 (default, Oct  2 2023, 19:30:04) 
[GCC 11.4.0] on linux
Type "help", "copyright", "credits" or "license" for more information.
>>> 
(myenv) kriminel@pop-os:~/Documents/Code/nigel$ flask run
 * Serving Flask app 'app'
 * Debug mode: off
WARNING: This is a development server. Do not use it in a production deployment. Use a production WSGI server instead.
 * Running on http://127.0.0.1:5000
Press CTRL+C to quit
^C(myenv) kriminel@pop-os:~/Documents/Code/nigel$ python
Python 3.8.18 (default, Oct  2 2023, 19:30:04) 
[GCC 11.4.0] on linux
Type "help", "copyright", "credits" or "license" for more information.
>>> 
(myenv) kriminel@pop-os:~/Documents/Code/nigel$ flask run
 * Serving Flask app 'app'
 * Debug mode: off
WARNING: This is a development server. Do not use it in a production deployment. Use a production WSGI server instead.
 * Running on http://127.0.0.1:5000
Press CTRL+C to quit
[2023-10-09 19:45:40,964] ERROR in app: Exception on / [GET]
Traceback (most recent call last):
  File "/home/kriminel/Documents/Code/nigel/myenv/lib/python3.8/site-packages/sqlalchemy/engine/base.py", line 1965, in _exec_single_context
    self.dialect.do_execute(
  File "/home/kriminel/Documents/Code/nigel/myenv/lib/python3.8/site-packages/sqlalchemy/engine/default.py", line 921, in do_execute
    cursor.execute(statement, parameters)
sqlite3.OperationalError: no such table: post

The above exception was the direct cause of the following exception:

Traceback (most recent call last):
  File "/home/kriminel/Documents/Code/nigel/myenv/lib/python3.8/site-packages/flask/app.py", line 1455, in wsgi_app
    response = self.full_dispatch_request()
  File "/home/kriminel/Documents/Code/nigel/myenv/lib/python3.8/site-packages/flask/app.py", line 869, in full_dispatch_request
    rv = self.handle_user_exception(e)
  File "/home/kriminel/Documents/Code/nigel/myenv/lib/python3.8/site-packages/flask/app.py", line 867, in full_dispatch_request
    rv = self.dispatch_request()
  File "/home/kriminel/Documents/Code/nigel/myenv/lib/python3.8/site-packages/flask/app.py", line 852, in dispatch_request
    return self.ensure_sync(self.view_functions[rule.endpoint])(**view_args)
  File "/home/kriminel/Documents/Code/nigel/app/routes.py", line 5, in home
    posts = Post.query.all()
  File "/home/kriminel/Documents/Code/nigel/myenv/lib/python3.8/site-packages/sqlalchemy/orm/query.py", line 2688, in all
    return self._iter().all()  # type: ignore
  File "/home/kriminel/Documents/Code/nigel/myenv/lib/python3.8/site-packages/sqlalchemy/orm/query.py", line 2842, in _iter
    result: Union[ScalarResult[_T], Result[_T]] = self.session.execute(
  File "/home/kriminel/Documents/Code/nigel/myenv/lib/python3.8/site-packages/sqlalchemy/orm/session.py", line 2262, in execute
    return self._execute_internal(
  File "/home/kriminel/Documents/Code/nigel/myenv/lib/python3.8/site-packages/sqlalchemy/orm/session.py", line 2144, in _execute_internal
    result: Result[Any] = compile_state_cls.orm_execute_statement(
  File "/home/kriminel/Documents/Code/nigel/myenv/lib/python3.8/site-packages/sqlalchemy/orm/context.py", line 293, in orm_execute_statement
    result = conn.execute(
  File "/home/kriminel/Documents/Code/nigel/myenv/lib/python3.8/site-packages/sqlalchemy/engine/base.py", line 1412, in execute
    return meth(
  File "/home/kriminel/Documents/Code/nigel/myenv/lib/python3.8/site-packages/sqlalchemy/sql/elements.py", line 516, in _execute_on_connection
    return connection._execute_clauseelement(
  File "/home/kriminel/Documents/Code/nigel/myenv/lib/python3.8/site-packages/sqlalchemy/engine/base.py", line 1635, in _execute_clauseelement
    ret = self._execute_context(
  File "/home/kriminel/Documents/Code/nigel/myenv/lib/python3.8/site-packages/sqlalchemy/engine/base.py", line 1844, in _execute_context
    return self._exec_single_context(
  File "/home/kriminel/Documents/Code/nigel/myenv/lib/python3.8/site-packages/sqlalchemy/engine/base.py", line 1984, in _exec_single_context
    self._handle_dbapi_exception(
  File "/home/kriminel/Documents/Code/nigel/myenv/lib/python3.8/site-packages/sqlalchemy/engine/base.py", line 2339, in _handle_dbapi_exception
    raise sqlalchemy_exception.with_traceback(exc_info[2]) from e
  File "/home/kriminel/Documents/Code/nigel/myenv/lib/python3.8/site-packages/sqlalchemy/engine/base.py", line 1965, in _exec_single_context
    self.dialect.do_execute(
  File "/home/kriminel/Documents/Code/nigel/myenv/lib/python3.8/site-packages/sqlalchemy/engine/default.py", line 921, in do_execute
    cursor.execute(statement, parameters)
sqlalchemy.exc.OperationalError: (sqlite3.OperationalError) no such table: post
[SQL: SELECT post.id AS post_id, post.title AS post_title, post.content AS post_content 
FROM post]
(Background on this error at: https://sqlalche.me/e/20/e3q8)
127.0.0.1 - - [09/Oct/2023 19:45:40] "GET / HTTP/1.1" 500 -
127.0.0.1 - - [09/Oct/2023 19:45:40] "GET /favicon.ico HTTP/1.1" 404 -
[2023-10-09 19:45:42,129] ERROR in app: Exception on / [GET]
Traceback (most recent call last):
  File "/home/kriminel/Documents/Code/nigel/myenv/lib/python3.8/site-packages/sqlalchemy/engine/base.py", line 1965, in _exec_single_context
    self.dialect.do_execute(
  File "/home/kriminel/Documents/Code/nigel/myenv/lib/python3.8/site-packages/sqlalchemy/engine/default.py", line 921, in do_execute
    cursor.execute(statement, parameters)
sqlite3.OperationalError: no such table: post

The above exception was the direct cause of the following exception:

Traceback (most recent call last):
  File "/home/kriminel/Documents/Code/nigel/myenv/lib/python3.8/site-packages/flask/app.py", line 1455, in wsgi_app
    response = self.full_dispatch_request()
  File "/home/kriminel/Documents/Code/nigel/myenv/lib/python3.8/site-packages/flask/app.py", line 869, in full_dispatch_request
    rv = self.handle_user_exception(e)
  File "/home/kriminel/Documents/Code/nigel/myenv/lib/python3.8/site-packages/flask/app.py", line 867, in full_dispatch_request
    rv = self.dispatch_request()
  File "/home/kriminel/Documents/Code/nigel/myenv/lib/python3.8/site-packages/flask/app.py", line 852, in dispatch_request
    return self.ensure_sync(self.view_functions[rule.endpoint])(**view_args)
  File "/home/kriminel/Documents/Code/nigel/app/routes.py", line 5, in home
    posts = Post.query.all()
  File "/home/kriminel/Documents/Code/nigel/myenv/lib/python3.8/site-packages/sqlalchemy/orm/query.py", line 2688, in all
    return self._iter().all()  # type: ignore
  File "/home/kriminel/Documents/Code/nigel/myenv/lib/python3.8/site-packages/sqlalchemy/orm/query.py", line 2842, in _iter
    result: Union[ScalarResult[_T], Result[_T]] = self.session.execute(
  File "/home/kriminel/Documents/Code/nigel/myenv/lib/python3.8/site-packages/sqlalchemy/orm/session.py", line 2262, in execute
    return self._execute_internal(
  File "/home/kriminel/Documents/Code/nigel/myenv/lib/python3.8/site-packages/sqlalchemy/orm/session.py", line 2144, in _execute_internal
    result: Result[Any] = compile_state_cls.orm_execute_statement(
  File "/home/kriminel/Documents/Code/nigel/myenv/lib/python3.8/site-packages/sqlalchemy/orm/context.py", line 293, in orm_execute_statement
    result = conn.execute(
  File "/home/kriminel/Documents/Code/nigel/myenv/lib/python3.8/site-packages/sqlalchemy/engine/base.py", line 1412, in execute
    return meth(
  File "/home/kriminel/Documents/Code/nigel/myenv/lib/python3.8/site-packages/sqlalchemy/sql/elements.py", line 516, in _execute_on_connection
    return connection._execute_clauseelement(
  File "/home/kriminel/Documents/Code/nigel/myenv/lib/python3.8/site-packages/sqlalchemy/engine/base.py", line 1635, in _execute_clauseelement
    ret = self._execute_context(
  File "/home/kriminel/Documents/Code/nigel/myenv/lib/python3.8/site-packages/sqlalchemy/engine/base.py", line 1844, in _execute_context
    return self._exec_single_context(
  File "/home/kriminel/Documents/Code/nigel/myenv/lib/python3.8/site-packages/sqlalchemy/engine/base.py", line 1984, in _exec_single_context
    self._handle_dbapi_exception(
  File "/home/kriminel/Documents/Code/nigel/myenv/lib/python3.8/site-packages/sqlalchemy/engine/base.py", line 2339, in _handle_dbapi_exception
    raise sqlalchemy_exception.with_traceback(exc_info[2]) from e
  File "/home/kriminel/Documents/Code/nigel/myenv/lib/python3.8/site-packages/sqlalchemy/engine/base.py", line 1965, in _exec_single_context
    self.dialect.do_execute(
  File "/home/kriminel/Documents/Code/nigel/myenv/lib/python3.8/site-packages/sqlalchemy/engine/default.py", line 921, in do_execute
    cursor.execute(statement, parameters)
sqlalchemy.exc.OperationalError: (sqlite3.OperationalError) no such table: post
[SQL: SELECT post.id AS post_id, post.title AS post_title, post.content AS post_content 
FROM post]
(Background on this error at: https://sqlalche.me/e/20/e3q8)
127.0.0.1 - - [09/Oct/2023 19:45:42] "GET / HTTP/1.1" 500 -
^C(myenv) kriminel@pop-os:~/Documents/Code/nigel$ 